<?xml version="1.0" ?>
<!-- =================================================================================== -->
<!-- |    This document was autogenerated by xacro from src/ARX_L5Pro_ros2/arx_l5pro_description/model/xacro/L5Pro.xacro | -->
<!-- |    EDITING THIS FILE BY HAND IS NOT RECOMMENDED                                 | -->
<!-- =================================================================================== -->
<robot name="lift_for_urdf">
  <material name="silver">
    <color rgba="0.700 0.700 0.700 1.000"/>
  </material>
  <gazebo>
    <self_collide>true</self_collide>
  </gazebo>
  <link name="world"/>
  <link name="base_link"/>
  <link name="arx_arm_base_link">
    <inertial>
      <origin rpy="0 0 0" xyz="-0.0001456050150032109 -7.271800715889125e-05 -0.03159354340734995"/>
      <mass value="1.1276471378072246"/>
      <inertia ixx="0.000524" ixy="-1e-06" ixz="2e-06" iyy="0.000527" iyz="-2e-06" izz="0.000538"/>
    </inertial>
    <visual>
      <origin rpy="-1.57079632679489 -5.682641097165828e-13 1.4835298641951802" xyz="0.007409306349121554 -0.041273942276757764 -0.09300023656190275"/>
      <geometry>
        <mesh filename="file:///home/evence/code_file/ros2_ws/install/arx_l5pro_description/share/arx_l5pro_description/model/meshes/arm_base_link.stl" scale="0.001 0.001 0.001"/>
      </geometry>
      <material name="silver"/>
    </visual>
    <collision>
      <origin rpy="-1.57079632679489 -5.682641097165828e-13 1.4835298641951802" xyz="0.007409306349121554 -0.041273942276757764 -0.09300023656190275"/>
      <geometry>
        <mesh filename="file:///home/evence/code_file/ros2_ws/install/arx_l5pro_description/share/arx_l5pro_description/model/meshes/arm_base_link.stl" scale="0.001 0.001 0.001"/>
      </geometry>
    </collision>
  </link>
  <link name="arx_arm_left_catch">
    <inertial>
      <origin rpy="0 0 0" xyz="0.018696230191015406 0.06784030061672763 0.007479650369965785"/>
      <mass value="0.2302561450054052"/>
      <inertia ixx="7.8e-05" ixy="-2.9e-05" ixz="4e-06" iyy="0.00014" iyz="1e-06" izz="0.000106"/>
    </inertial>
    <visual>
      <origin rpy="-1.5707963267948564 -5.682734089846881e-15 1.5707963267948966" xyz="-0.26272783144624917 -0.24174086015772833 -0.13086553021654831"/>
      <geometry>
        <mesh filename="file:///home/evence/code_file/ros2_ws/install/arx_l5pro_description/share/arx_l5pro_description/model/meshes/arm_left_catch.stl" scale="0.001 0.001 0.001"/>
      </geometry>
      <material name="silver"/>
    </visual>
    <collision>
      <origin rpy="-1.5707963267948564 -5.682734089846881e-15 1.5707963267948966" xyz="-0.26272783144624917 -0.24174086015772833 -0.13086553021654831"/>
      <geometry>
        <mesh filename="file:///home/evence/code_file/ros2_ws/install/arx_l5pro_description/share/arx_l5pro_description/model/meshes/arm_left_catch.stl" scale="0.001 0.001 0.001"/>
      </geometry>
    </collision>
  </link>
  <link name="arx_arm_right_catch">
    <inertial>
      <origin rpy="0 0 0" xyz="0.01869623023343539 -0.06784065890719916 0.0033237364806670278"/>
      <mass value="0.23025614445804038"/>
      <inertia ixx="8e-05" ixy="2.9e-05" ixz="-1.3e-05" iyy="0.000142" iyz="5e-06" izz="0.000106"/>
    </inertial>
    <visual>
      <origin rpy="-1.5707963267948528 -5.743024426267096e-15 1.570796326794896" xyz="-0.29017064732829795 -0.5171716895291774 -0.028033322064966698"/>
      <geometry>
        <mesh filename="file:///home/evence/code_file/ros2_ws/install/arx_l5pro_description/share/arx_l5pro_description/model/meshes/arm_right_catch.stl" scale="0.001 0.001 0.001"/>
      </geometry>
      <material name="silver"/>
    </visual>
    <collision>
      <origin rpy="-1.5707963267948528 -5.743024426267096e-15 1.570796326794896" xyz="-0.29017064732829795 -0.5171716895291774 -0.028033322064966698"/>
      <geometry>
        <mesh filename="file:///home/evence/code_file/ros2_ws/install/arx_l5pro_description/share/arx_l5pro_description/model/meshes/arm_right_catch.stl" scale="0.001 0.001 0.001"/>
      </geometry>
    </collision>
  </link>
  <link name="arx_arm_link6">
    <inertial>
      <origin rpy="0 0 0" xyz="0.04623807673208906 -3.591191717127893e-06 -0.02029844922949381"/>
      <mass value="1.6175866280512115"/>
      <inertia ixx="0.002553" ixy="-1e-06" ixz="0.000719" iyy="0.002685" iyz="7e-06" izz="0.001423"/>
    </inertial>
    <visual>
      <origin rpy="3.1415926535897873 -5.716212816269276e-15 1.5707963267948957" xyz="0.07808022871553331 -0.08756556935939981 0.017299995001220148"/>
      <geometry>
        <mesh filename="file:///home/evence/code_file/ros2_ws/install/arx_l5pro_description/share/arx_l5pro_description/model/meshes/arm_link6.stl" scale="0.001 0.001 0.001"/>
      </geometry>
      <material name="silver"/>
    </visual>
    <collision>
      <origin rpy="3.1415926535897873 -5.716212816269276e-15 1.5707963267948957" xyz="0.07808022871553331 -0.08756556935939981 0.017299995001220148"/>
      <geometry>
        <mesh filename="file:///home/evence/code_file/ros2_ws/install/arx_l5pro_description/share/arx_l5pro_description/model/meshes/arm_link6.stl" scale="0.001 0.001 0.001"/>
      </geometry>
    </collision>
  </link>
  <link name="arx_arm_link5">
    <inertial>
      <origin rpy="0 0 0" xyz="0.0035265339971426446 -1.6982469496496013e-05 0.053397693166843424"/>
      <mass value="1.682735565009155"/>
      <inertia ixx="0.002208" ixy="2e-06" ixz="-0.000168" iyy="0.002158" iyz="-1e-06" izz="0.000703"/>
    </inertial>
    <visual>
      <origin rpy="-4.2935784856134613e-13 3.6706618321830196e-15 -1.270846849966628" xyz="0.03472708149774527 -0.052113616932989 -0.057241042913607765"/>
      <geometry>
        <mesh filename="file:///home/evence/code_file/ros2_ws/install/arx_l5pro_description/share/arx_l5pro_description/model/meshes/arm_link5.stl" scale="0.001 0.001 0.001"/>
      </geometry>
      <material name="silver"/>
    </visual>
    <collision>
      <origin rpy="-4.2935784856134613e-13 3.6706618321830196e-15 -1.270846849966628" xyz="0.03472708149774527 -0.052113616932989 -0.057241042913607765"/>
      <geometry>
        <mesh filename="file:///home/evence/code_file/ros2_ws/install/arx_l5pro_description/share/arx_l5pro_description/model/meshes/arm_link5.stl" scale="0.001 0.001 0.001"/>
      </geometry>
    </collision>
  </link>
  <link name="arx_arm_link4">
    <inertial>
      <origin rpy="0 0 0" xyz="0.04175138112968485 -0.02182634772751651 -0.033369810917049436"/>
      <mass value="0.3614635103426687"/>
      <inertia ixx="0.000637" ixy="6.1e-05" ixz="0.00026" iyy="0.000712" iyz="-6.3e-05" izz="0.000483"/>
    </inertial>
    <visual>
      <origin rpy="-1.5707963267949514 -6.287079817982621e-15 1.5707963267948966" xyz="0.0029714091296810983 -0.027199999999898253 0.13399227229218827"/>
      <geometry>
        <mesh filename="file:///home/evence/code_file/ros2_ws/install/arx_l5pro_description/share/arx_l5pro_description/model/meshes/arm_link4.stl" scale="0.001 0.001 0.001"/>
      </geometry>
      <material name="silver"/>
    </visual>
    <collision>
      <origin rpy="-1.5707963267949514 -6.287079817982621e-15 1.5707963267948966" xyz="0.0029714091296810983 -0.027199999999898253 0.13399227229218827"/>
      <geometry>
        <mesh filename="file:///home/evence/code_file/ros2_ws/install/arx_l5pro_description/share/arx_l5pro_description/model/meshes/arm_link4.stl" scale="0.001 0.001 0.001"/>
      </geometry>
    </collision>
  </link>
  <link name="arx_arm_link3">
    <inertial>
      <origin rpy="0 0 0" xyz="0.14929510892781805 -0.02659292514479473 -0.055156332017428936"/>
      <mass value="2.8273308884294726"/>
      <inertia ixx="0.002651" ixy="-0.000296" ixz="0.002042" iyy="0.02629" iyz="-1.4e-05" izz="0.025936"/>
    </inertial>
    <visual>
      <origin rpy="-1.5707963267949514 -6.287079817982629e-15 1.5707963267948968" xyz="0.2479744091296824 -0.027249999999899337 0.07399227229218361"/>
      <geometry>
        <mesh filename="file:///home/evence/code_file/ros2_ws/install/arx_l5pro_description/share/arx_l5pro_description/model/meshes/arm_link3.stl" scale="0.001 0.001 0.001"/>
      </geometry>
      <material name="silver"/>
    </visual>
    <collision>
      <origin rpy="-1.5707963267949514 -6.287079817982629e-15 1.5707963267948968" xyz="0.2479744091296824 -0.027249999999899337 0.07399227229218361"/>
      <geometry>
        <mesh filename="file:///home/evence/code_file/ros2_ws/install/arx_l5pro_description/share/arx_l5pro_description/model/meshes/arm_link3.stl" scale="0.001 0.001 0.001"/>
      </geometry>
    </collision>
  </link>
  <link name="arx_arm_link2">
    <inertial>
      <origin rpy="0 0 0" xyz="-0.1297314818340554 -0.02620257200255764 3.909377900336575e-05"/>
      <mass value="3.2738322976375356"/>
      <inertia ixx="0.001798" ixy="0.000244" ixz="-4e-06" iyy="0.044232" iyz="-1e-06" izz="0.044191"/>
    </inertial>
    <visual>
      <origin rpy="-1.5707963267949514 -6.287079817982719e-15 1.5707963267948968" xyz="-0.016025590870325606 -0.027249999999964903 0.07399227229218396"/>
      <geometry>
        <mesh filename="file:///home/evence/code_file/ros2_ws/install/arx_l5pro_description/share/arx_l5pro_description/model/meshes/arm_link2.stl" scale="0.001 0.001 0.001"/>
      </geometry>
      <material name="silver"/>
    </visual>
    <collision>
      <origin rpy="-1.5707963267949514 -6.287079817982719e-15 1.5707963267948968" xyz="-0.016025590870325606 -0.027249999999964903 0.07399227229218396"/>
      <geometry>
        <mesh filename="file:///home/evence/code_file/ros2_ws/install/arx_l5pro_description/share/arx_l5pro_description/model/meshes/arm_link2.stl" scale="0.001 0.001 0.001"/>
      </geometry>
    </collision>
  </link>
  <link name="arx_arm_link1">
    <inertial>
      <origin rpy="0 0 0" xyz="0.005039564140590291 0.007740648292756791 -0.020896953872817432"/>
      <mass value="0.2814477837021216"/>
      <inertia ixx="0.000307" ixy="-1.5e-05" ixz="3.6e-05" iyy="0.000135" iyz="3.2e-05" izz="0.00028"/>
    </inertial>
    <visual>
      <origin rpy="-1.5707963267949514 -6.28707981798273e-15 1.5707963267948968" xyz="0.003974409129652747 2.7743000283219855e-14 0.026992272292184087"/>
      <geometry>
        <mesh filename="file:///home/evence/code_file/ros2_ws/install/arx_l5pro_description/share/arx_l5pro_description/model/meshes/arm_link1.stl" scale="0.001 0.001 0.001"/>
      </geometry>
      <material name="silver"/>
    </visual>
    <collision>
      <origin rpy="-1.5707963267949514 -6.28707981798273e-15 1.5707963267948968" xyz="0.003974409129652747 2.7743000283219855e-14 0.026992272292184087"/>
      <geometry>
        <mesh filename="file:///home/evence/code_file/ros2_ws/install/arx_l5pro_description/share/arx_l5pro_description/model/meshes/arm_link1.stl" scale="0.001 0.001 0.001"/>
      </geometry>
    </collision>
  </link>
  <joint name="arx_catch_joint1" type="prismatic">
    <origin rpy="0 0 0" xyz="0.075228 -0.084998 -0.005"/>
    <parent link="arx_arm_link6"/>
    <child link="arx_arm_left_catch"/>
    <axis xyz="0.087156 0.996195 0.0"/>
    <limit effort="100" lower="-0.0445" upper="0.0" velocity="100"/>
  </joint>
  <joint name="arx_catch_joint2" type="prismatic">
    <origin rpy="0 0 0" xyz="0.075228 0.085002 -0.005"/>
    <parent link="arx_arm_link6"/>
    <child link="arx_arm_right_catch"/>
    <axis xyz="0.087156 0.996195 0.0"/>
    <limit effort="100" lower="0.0" upper="0.0445" velocity="100"/>
  </joint>
  <joint name="arx_arm_joint6" type="continuous">
    <origin rpy="0 0 0" xyz="0.02895 -0.0 0.0845"/>
    <parent link="arx_arm_link5"/>
    <child link="arx_arm_link6"/>
    <axis xyz="-1.0 -0.0 -0.0"/>
  </joint>
  <joint name="arx_arm_joint5" type="continuous">
    <origin rpy="0 0 0" xyz="0.07025 -0.0272 -0.0845"/>
    <parent link="arx_arm_link4"/>
    <child link="arx_arm_link5"/>
    <axis xyz="0.0 0.0 -1.0"/>
  </joint>
  <joint name="arx_arm_joint4" type="continuous">
    <origin rpy="0 0 0" xyz="0.245003 -5e-05 -0.06"/>
    <parent link="arx_arm_link3"/>
    <child link="arx_arm_link4"/>
    <axis xyz="-0.0 1.0 0.0"/>
  </joint>
  <joint name="arx_arm_joint3" type="continuous">
    <origin rpy="0 0 0" xyz="-0.264 0.0 0.0"/>
    <parent link="arx_arm_link2"/>
    <child link="arx_arm_link3"/>
    <axis xyz="-0.0 1.0 0.0"/>
  </joint>
  <joint name="arx_arm_joint2" type="continuous">
    <origin rpy="0 0 0" xyz="0.022299 0.025403 -0.047"/>
    <parent link="arx_arm_link1"/>
    <child link="arx_arm_link2"/>
    <axis xyz="-0.0 1.0 0.0"/>
  </joint>
  <joint name="arx_arm_joint1" type="continuous">
    <origin rpy="0 0 0" xyz="0.0 0.0 -0.0565"/>
    <parent link="arx_arm_base_link"/>
    <child link="arx_arm_link1"/>
    <axis xyz="-0.0 -0.0 1.0"/>
  </joint>
  <joint name="arm_fixed" type="fixed">
    <parent link="base_link"/>
    <child link="arx_arm_base_link"/>
    <origin rpy="0 3.141592653589793 0" xyz="0.0 0.0 0.0"/>
  </joint>
  <!-- 与世界坐标固定-->
  <joint name="fixed" type="fixed">
    <parent link="world"/>
    <child link="base_link"/>
  </joint>
</robot>
